Workbook

Sheet NBCS Financial Report
A4: Reference: | C4: Nebraska Accounting Code Manual for Counties | D4: at the following web link:
D5: http://auditors.nebraska.gov/County_Info/County_Manual.html
C6: For Codes listed below, refer to Chapter 4 (Revenue) and Chapter 5 (Expenditures)
A8: Municipality or County: | D8: Fiscal Year Ending:
A10: Item No. | B10: Item | D10: Estimated for this Fiscal Year | E10: Actual for this Fiscal Year | F10: Estimates for Next Fiscal Year
A12: CASH BALANCE | C12: BEGINNING CASH BALANCE | E12: =+D12 -> 0
A13: For this Fiscal Year, if Actual was not equal to Estimated, explain:
A15: 301-329, 350-359, 398-540, 590, and Township Sources | C15: LOCAL REVENUE SOURCES (COUNTY & MUNICIPALITY) | D15: =+'Revenu Data'!D41 -> 0 | E15: =+'Revenu Data'!E41 -> 0 | F15: =+'Revenu Data'!F41 -> 0
A16: 301-309 | C16: Property Tax
A17: 310 | C17: Inheritance Tax
A18: 311-313 | C18: Local Sales Tax
A19: 314-315 | C19: 911 Tax and Lodging Tax
A20: 316.01 | C20: Wheel Tax
A21: 317 | C21: Special Assessments (county) | G21: What's the difference with 490.02? Are these just special assessments by counties?
A22: 318 | C22: Occupation Tax
A23: 320-329 | C23: License and Permit revenues
A24: 398-540 | C24: MISCELLANEOUS REVENUE
A25: 490-491 | C25: Special Assessment - Paving (cities, villages) | G25: What's the difference with 317?
A26: 510 | C26: Interest on Investments
A27: 520.01 | C27: Proceeds from the Sale of Bonds
A28: 520.02 | C28: Registered Warrants/Loans
A29: 530 | C29: Sale of Property, Supplies, Materials
A30: 534.01 | C30: Donations (money only)
C31: Any Other Miscellaneous Revenue
A32: 350-359 | C32: INTERGOVERNMENTAL REVENUE
A33: 351.04 | C33: Interlocal Government Payments - Roads
A34: 353.02 | C34: In Lieu of Taxes - 5% Gross Revenue
C35: Any Other Intergovenmental Revenue
A36: 590 | C36: COUNTY TRANSFERS
A37: 590.01 | C37: Transfers - Local Matching Funds
A38: 590.02 | C38: Transfers - Inter-fund
A39: 590.03 | C39: Transfers - Sinking Funds
A40: 590.04 | C40: Transfers - Closed funds
C41: Any Other Transfers (Specify)
C42: TOWNSHIP SOURCES (Specify)
C45: TOTAL FROM LOCAL SOURCES | D45: =SUM(D16:D44) -> 0 | E45: =SUM(E16:E44) -> 0 | F45: =SUM(F16:F44) -> 0
A46: 340-349 | C46: STATE REVENUE SOURCES | D46: =+'Revenu Data'!D63 -> 0 | E46: =+'Revenu Data'!E63 -> 0.01 | F46: =+'Revenu Data'!F63 -> 0
A47: 340.20 | C47: State Natural Disaster | G47: ??? | H47: is this state-aid emergency flooding relief?
A48: 344.01 | C48: Homestead Exemption Allocation
A49: 344.05 | C49: Property Tax Credit
...

Sheet Revenu Data
A2: ROADS & STREETS FINANCIAL REPORT
A3: TO
A4: BOARD OF PUBLIC ROADS CLASSIFICATIONS AND STANDARDS
C6: Reference Chapter 4 of the | D6: Nebraska Accounting Code Manual for Counties | H6: County Accounting Manual | M6: County Accounting Manual
H7: Numerical Revenue Codes found on pages: | M7: Citations and Definitions on these pages:
A8: Municipality or County: | B8: =+'NBCS Financial Report'!B8:C8 -> 0 | D8: Fiscal Year Ending: | E8: =+'NBCS Financial Report'!E8 -> 0 | H8: Combined File Page x/78 | I8: Chapter | J8: Section | K8: Page | M8: Combined File Page x/78 | N8: Chapter | O8: Section | P8: Page
C9: BEGINNING CASH BALANCE
A10: Item No. | B10: Item | D10: Estimated Fiscal Year | E10: Actual Fiscal Year | F10: Next Fiscal Year Estimates
C11: LOCAL SOURCES (COUNTY & MUNICIPALITY)
A12: 301-309 | C12: Property Tax | H12: 32 | I12: 4 | J12: A | K12: 1 | M12: 44 | N12: 4 | O12: B | P12: 1
A13: 310 | C13: Inheritance Tax | H13: 32 | I13: 4 | J13: A | K13: 1 | M13: 44 | N13: 4 | O13: B | P13: 1
A14: 311-313 | C14: Local Sales Tax | H14: 32 | I14: 4 | J14: A | K14: 1 | M14: 44 | N14: 4 | O14: B | P14: 1
A15: 314-315 | C15: 911 Tax and Lodging Tax | H15: 32 | I15: 4 | J15: A | K15: 1 | M15: 44 | N15: 4 | O15: B | P15: 1
A16: 316.01 | C16: Wheel Tax | H16: 32 | I16: 4 | J16: A | K16: 1 | M16: 44 | N16: 4 | O16: B | P16: 1
A17: 317 | C17: Special Assessments (county) | H17: 32 | I17: 4 | J17: A | K17: 1 | M17: 44 | N17: 4 | O17: B | P17: 1
A18: 318 | C18: Occupation Tax | H18: 33 | I18: 4 | J18: A | K18: 2 | M18: 44 | N18: 4 | O18: B | P18: 1
A19: 320-329 | C19: License and Permit revenues | H19: 33 | I19: 4 | J19: A | K19: 2 | M19: 45 | N19: 4 | O19: B | P19: 2-3
A20: 398-579 | C20: MISCELLANEOUS REVENUE
A21: 490-491 | C21: Special Assessment - Paving (cities, villages) | H21: 41 | I21: 4 | J21: A | K21: 10 | M21: 55 | N21: 4 | O21: B | P21: 12
A22: 510 | C22: Interest on Investments | H22: 42 | I22: 4 | J22: A | K22: 11 | M22: 56 | N22: 4 | O22: B | P22: 13
A23: 520.01 | C23: Proceeds from the Sale of Bonds | H23: 42 | I23: 4 | J23: A | K23: 11 | M23: 56 | N23: 4 | O23: B | P23: 13
A24: 520.02 | C24: Registered Warrants/Loans | H24: 42 | I24: 4 | J24: A | K24: 11 | M24: 56 | N24: 4 | O24: B | P24: 13
A25: 530 | C25: Sale of Property, Supplies, Materials | H25: 42 | I25: 4 | J25: A | K25: 11 | M25: 56 | N25: 4 | O25: B | P25: 13
A26: 534.01 | C26: Donations (money only) | H26: 42 | I26: 4 | J26: A | K26: 11 | M26: 57 | N26: 4 | O26: B | P26: 14
C27: Any Other Miscellaneous Revenue
A28: 350-359 | C28: INTERGOVERNMENTAL REVENUE | H28: 36 | I28: 4 | J28: A | K28: 5
A29: 351.04 | C29: Interlocal Government Payments - Roads | H29: 36 | I29: 4 | J29: A | K29: 5
A30: 353.02 | C30: In Lieu of Taxes - 5% Gross Revenue | H30: 36 | I30: 4 | J30: A | K30: 5 | M30: 49 | N30: 4 | O30: B | P30: 6
C31: Any Other Intergovenmental Revenue
A32: 590 | C32: COUNTY TRANSFERS | H32: 43 | I32: 4 | J32: A | K32: 12
A33: 590.01 | C33: Transfers - Local Matching Funds | H33: 43 | I33: 4 | J33: A | K33: 12 | M33: 57 | N33: 4 | O33: B | P33: 14
A34: 590.02 | C34: Transfers - Inter-fund | H34: 43 | I34: 4 | J34: A | K34: 12 | M34: 57 | N34: 4 | O34: B | P34: 14
A35: 590.03 | C35: Transfers - Sinking Funds | H35: 43 | I35: 4 | J35: A | K35: 12
A36: 590.04 | C36: Transfers - Closed funds | H36: 43 | I36: 4 | J36: A | K36: 12
C37: Any Other Transfers
C38: ALL TOWNSHIPS REVENUES FOR ROADS
C41: TOTAL REVENUES FROM LOCAL SOURCES | D41: =SUM(D12:D40) -> 0 | E41: =SUM(E12:E40) -> 0 | F41: =SUM(F12:F40) -> 0
A43: 340-349 | C43: STATE REVENUE SOURCES
A44: 340.20 | C44: State Natural Disaster | H44: 35 | I44: 4 | J44: A | K44: 4
A45: 344.01 | C45: Homestead Exemption Allocation | H45: 36 | I45: 4 | J45: A | K45: 5 | M45: 48 | N45: 4 | O45: B | P45: 5
...

Sheet Expend Data
A1: Municipality or County: | B1: =+'NBCS Financial Report'!B8:C8 -> 0 | D1: Fiscal Year Ending: | E1: =+'NBCS Financial Report'!E8 -> 0 | H1: County Accounting Manual Numerical Expenditure Codes | M1: County Accounting Manual Citations and Definitions
A2: Item No. | B2: Item | D2: Budget Fiscal Year | E2: Actual Expended Fiscal Year | F2: Budget Next Year | H2: Combined File Page x/78 | I2: Chapter | J2: Section | K2: Page | M2: Combined File Page x/78 | N2: Chapter | O2: Section | P2: Page
A3: PERSONAL SERVICES - 1 | M3: 74 | N3: 6 | O3: C | P3: 1
A4: 0300 - 0700 | C4: SALARIES - REGULAR & PART-TIME EMPLOYEES | H4: 62 | I4: 5 | J4: B | K4: 1 | M4: 74 | N4: 6 | O4: C | P4: 1
C5: INCLUDING OVERTIME, SPECIAL OVERTIME, HOLIDAY, BACK, VACATION AND SICK PAY | H5: 62 | I5: 5 | J5: B | K5: 1
B6: 0301/0401 | C6: Administrative | H6: 62 | I6: 5 | J6: B | K6: 1
C7: Engineering
B8: 0303/0403 | C8: Maintenance | H8: 62 | I8: 5 | J8: B | K8: 1
B9: 0304/0404 | C9: Construction | H9: 62 | I9: 5 | J9: B | K9: 1
B10: 0305/0405 | C10: Clerical | H10: 62 | I10: 5 | J10: B | K10: 1
B11: 0306/0406 | C11: Custodial | H11: 62 | I11: 5 | J11: B | K11: 1
C12: Other Salaries Not Reported Above
A13: 0800 | C13: INSURANCE PREMIUMS | H13: 63 | I13: 5 | J13: B | K13: 2 | M13: 74 | N13: 6 | O13: C | P13: 1
B14: 0801 | C14: Workmans Compensation | H14: 63 | I14: 5 | J14: B | K14: 2
B15: 0802 | C15: Health & Accident | H15: 63 | I15: 5 | J15: B | K15: 2
B16: 0803 | C16: Group | H16: 63 | I16: 5 | J16: B | K16: 2
B17: 0804 | C17: Life | H17: 63 | I17: 5 | J17: B | K17: 2
C18: Other insurance premiums
A19: 0900 | C19: RETIREMENT CONTRIBUTIONS | H19: 63 | I19: 5 | J19: B | K19: 2 | M19: 74 | N19: 6 | O19: C | P19: 1
A20: 1000 | C20: FICA - COUNTY (or MUNICIPALITY) SHARE | H20: 63 | I20: 5 | J20: B | K20: 2 | M20: 74 | N20: 6 | O20: C | P20: 1
A21: 1100 | C21: UNIFORM ALLOWANCE | H21: 63 | I21: 5 | J21: B | K21: 2 | M21: 74 | N21: 6 | O21: C | P21: 1
A22: 1200 | C22: INSURANCE ALLOWANCE | H22: 63 | I22: 5 | J22: B | K22: 2
A23: 1300 | C23: OTHER PERSONAL SERVICES | H23: 63 | I23: 5 | J23: B | K23: 2 | M23: 74 | N23: 6 | O23: C | P23: 1
A24: 1400 | C24: MISCELLANEOUS PERSONAL SERVICES | H24: 63 | I24: 5 | J24: B | K24: 2 | M24: 75 | N24: 6 | O24: C | P24: 2
A25: 1500 | C25: UNEMPLOYMENT CONTRIBUTIONS | H25: 63 | I25: 5 | J25: B | K25: 2 | M25: 75 | N25: 6 | O25: C | P25: 2
A26: 1600 | C26: COBRA REFUND | H26: 63 | I26: 5 | J26: B | K26: 2
C27: Other Personal Services not reported above
C28: PERSONAL SERVICES - 1 SUB-TOTAL: | D28: =SUM(D6:D27) -> 0 | E28: =SUM(E6:E27) -> 0 | F28: =SUM(F6:F27) -> 0
A29: OPERATING EXPENSES - 2 | M29: 75 | N29: 6 | O29: C | P29: 2
A30: 0100 | C30: POSTAL SERVICES | H30: 63 | I30: 5 | J30: B | K30: 2 | M30: 75 | N30: 6 | O30: C | P30: 2
A31: 0200 | C31: TELEPHONE SERVICES | H31: 63 | I31: 5 | J31: B | K31: 2 | M31: 75 | N31: 6 | O31: C | P31: 2
A32: 0400 | C32: RENTAL EXPENSES | H32: 63 | I32: 5 | J32: B | K32: 2
A33: 0500 | C33: UTILITIES | H33: 64 | I33: 5 | J33: B | K33: 3 | M33: 75 | N33: 6 | O33: C | P33: 2
B34: 0501 | C34: Light (Electricity) | H34: 64 | I34: 5 | J34: B | K34: 3
B35: 0502 | C35: Water | H35: 64 | I35: 5 | J35: B | K35: 3
B36: 0503 | C36: Heating Fuels | H36: 64 | I36: 5 | J36: B | K36: 3
B37: 0504 | C37: Sewer | H37: 64 | I37: 5 | J37: B | K37: 3
B38: 0505 | C38: Garbage | H38: 64 | I38: 5 | J38: B | K38: 3
C39: Other Utilities
A40: 0600 | C40: INSURANCE PREMIUMS | M40: 75 | N40: 6 | O40: C | P40: 2
...
